Workbook

Sheet 19_Instructions
A1: STEP | B1: INSTRUCTION
A2: 1 | B2: Open this workbook in Microsoft Excel Desktop.
A3: 2 | B3: Complete the Food Delivery cleaning/lookup/day extraction tasks using the prepared sheets. The cleaned result is already demonstrated in 01B_Cleaned_Orders.
A4: 3 | B4: For the City Summary, use Insert > PivotTable on the cleaned data. Put City in Rows, Order ID in Values (Count), Delivery Charge in Values (Sum), then insert a Column/Bar PivotChart.
A5: 4 | B5: For the Dashboard, create PivotTables/Charts and insert a City slicer: PivotTable Analyze > Insert Slicer > City. Connect the slicer to relevant PivotTables using Report Connections.
A6: 5 | B6: For Developer-tab tasks, enable Developer: File > Options > Customize Ribbon > check Developer.
A7: 6 | B7: For macro-recorder tasks, use Developer > Record Macro. Do not edit VBA for the task where the assignment explicitly says recorder only.
A8: 7 | B8: For written VBA tasks, press Alt+F11 > Insert > Module, copy the required code from 18_VBA_Code, then run it.
A9: 8 | B9: Save the final workbook as Excel Macro-Enabled Workbook (*.xlsm).
A10: 9 | B10: After reopening the .xlsm, choose Enable Content/Enable Macros if prompted and test the macros.
A11: 10 | B11: For the Power Query task, the provided macro uses ThisWorkbook.RefreshAll. The exact refresh behavior depends on whether the workbook has an actual Power Query connection.
A12: 11 | B12: For the Zomato PDF task, run Export_Zomato_PDF. It saves to the Windows Desktop as Zomato_Sales_Dashboard.pdf.
A13: 12 | B13: For the ChatGPT/Copilot task, the exact prompt is stored in 17_Prompt_Used.

Sheet 01_Food_Orders_Cleaning
A1: Order ID | B1: Restaurant ID | C1: City | D1: Delivery Date | E1: Delivery Partner | F1: Delivery Time (min) | G1: Delivery Charge | H1: Status
A2: ORD0001 | B2: 1003 | C2: Surat | D2: 01-08-2026 | F2: 29 | G2: 257.61 | H2: Delivered
A3: ORD0002 | B3: 1002 | C3: Surat | D3: 09-08-2026 | E3: Rahul | F3: 38 | G3: 342.59 | H3: Delivered
A4: ORD0003 | B4: 1009 | C4: Rajkot | D4: 23-08-2026 | E4: Rahul | F4: 54 | G4: 313.22 | H4: Delivered
A5: ORD0004 | B5: 1005 | C5: Rajkot | D5: 07-08-2026 | E5: Neha | F5: 25 | G5: 220.68 | H5: Delivered
A6: ORD0005 | B6: 1006 | C6: Gandhinagar | D6: 11-08-2026 | E6: Karan | F6: 29 | G6: 336.58 | H6: Delivered
A7: ORD0006 | B7: 1009 | C7: Surat | D7: 09-08-2026 | E7: Karan | F7: 29 | G7: 173.89 | H7: Delivered
A8: ORD0007 | B8: 1009 | C8: Ahmedabad | D8: 14-08-2026 | E8: Karan | F8: 50 | G8: 128.13 | H8: Cancelled
A9: ORD0008 | B9: 1007 | C9: Surat | D9: 10-08-2026 | E9: Mehul | F9: 43 | G9: 220.6 | H9: Delivered
A10: ORD0009 | B10: 1010 | C10: Gandhinagar | D10: 18-08-2026 | E10: Sneha | F10: 51 | G10: 172.48 | H10: Delivered
A11: ORD0010 | B11: 1008 | C11: Vadodara | D11: 04-08-2026 | E11: Sneha | F11: 43 | G11: 58 | H11: Delivered
A12: ORD0011 | B12: 1009 | C12: Surat | D12: 13-08-2026 | E12: Rahul | F12: 24 | G12: 182.28 | H12: Delivered
A13: ORD0012 | B13: 1003 | C13: Ahmedabad | D13: 18-08-2026 | E13: Sneha | F13: 40 | G13: 95.45 | H13: Delivered
A14: ORD0013 | B14: 1004 | C14: Rajkot | D14: 02-08-2026 | E14: Amit | F14: 52 | G14: 81.72 | H14: Delivered
... A22: ORD0021 | B22: 1007 | C22: Vadodara | D22: 04-08-2026 | E22: Neha | F22: 20 | G22: 113.69 | H22: Delivered
A23: ORD0022 | B23: 1004 | C23: Surat | D23: 25-08-2026 | F23: 42 | G23: 55.23 | H23: Cancelled
A24: ORD0023 | B24: 1008 | C24: Vadodara | D24: 08-08-2026 | E24: Priya | F24: 25 | G24: 122.55 | H24: Delivered
A25: ORD0024 | B25: 1010 | C25: Surat | D25: 06-08-2026 | E25: Mehul | F25: 21 | G25: 49.29 | H25: Delivered
A26: ORD0025 | B26: 1010 | C26: Vadodara | D26: 02-08-2026 | F26: 19 | G26: 125.89 | H26: Delivered
A27: ORD0026 | B27: 1004 | C27: Rajkot | D27: 28-08-2026 | E27: Priya | F27: 46 | G27: 205.71 | H27: Delivered
A28: ORD0027 | B28: 1006 | C28: Vadodara | D28: 09-08-2026 | E28: Rahul | F28: 42 | G28: 228.59 | H28: Delivered
A29: ORD0028 | B29: 1003 | C29: Gandhinagar | D29: 18-08-2026 | E29: Mehul | F29: 35 | G29: 303.04 | H29: Delivered
A30: ORD0029 | B30: 1004 | C30: Vadodara | D30: 09-08-2026 | E30: Neha | F30: 40 | G30: 300 | H30: Cancelled
A31: ORD0030 | B31: 1008 | C31: Surat | D31: 18-08-2026 | E31: Priya | F31: 49 | G31: 165.77 | H31: Delivered
A32: ORD0031 | B32: 1007 | C32: Gandhinagar | D32: 07-08-2026 | E32: Neha | F32: 23 | G32: 55.69 | H32: Cancelled
A33: ORD0032 | B33: 1006 | C33: Surat | D33: 02-08-2026 | E33: Neha | F33: 30 | G33: 212.88 | H33: Delivered
A34: ORD0033 | B34: 1009 | C34: Vadodara | D34: 25-08-2026 | E34: Rahul | F34: 25 | G34: 334.05 | H34: Delivered
A35: ORD0034 | B35: 1002 | C35: Ahmedabad | D35: 19-08-2026 | E35: Amit | F35: 29 | G35: 119.88 | H35: Delivered
A36: ORD0035 | B36: 1006 | C36: Rajkot | D36: 19-08-2026 | E36: Mehul | F36: 38 | G36: 340.85 | H36: Delivered
A37: ORD0036 | B37: 1004 | C37: Gandhinagar | D37: 21-08-2026 | E37: Mehul | F37: 36 | G37: 41.05 | H37: Delivered
A38: ORD0037 | B38: 1001 | C38: Ahmedabad | D38: 30-08-2026 | E38: Mehul | F38: 37 | G38: 315.59 | H38: Delivered
A39: ORD0038 | B39: 1002 | C39: Ahmedabad | D39: 30-08-2026 | F39: 39 | G39: 324.84 | H39: Delivered
A40: ORD0039 | B40: 1008 | C40: Vadodara | D40: 14-08-2026 | E40: Sneha | F40: 40 | G40: 83.33 | H40: Cancelled
A41: ORD0040 | B41: 1005 | C41: Surat | D41: 18-08-2026 | E41: Priya | F41: 41 | G41: 320.1 | H41: Cancelled
A42: ORD0041 | B42: 1005 | C42: Gandhinagar | D42: 18-08-2026 | E42: Priya | F42: 23 | G42: 79.74 | H42: Delivered
A43: ORD0042 | B43: 1005 | C43: Gandhinagar | D43: 05-08-2026 | F43: 21 | G43: 119.73 | H43: Delivered
A44: ORD0043 | B44: 1003 | C44: Ahmedabad | D44: 18-08-2026 | F44: 38 | G44: 288.43 | H44: Cancelled
A45: ORD0044 | B45: 1002 | C45: Vadodara | D45: 07-08-2026 | E45: Sneha | F45: 26 | G45: 323.5 | H45: Cancelled
A46: ORD0045 | B46: 1007 | C46: Gandhinagar | D46: 02-08-2026 | E46: Sneha | F46: 47 | G46: 290.48 | H46: Cancelled
A47: ORD0046 | B47: 1006 | C47: Surat | D47: 10-08-2026 | E47: Rahul | F47: 23 | G47: 75.76 | H47: Cancelled
...

Sheet 01B_Cleaned_Orders
A1: Order ID | B1: Restaurant ID | C1: City | D1: Delivery Date | E1: Delivery Partner | F1: Delivery Time (min) | G1: Delivery Charge | H1: Status
A2: ORD0001 | B2: 1003 | C2: Surat | D2: 46235 | E2: Unassigned | F2: 29 | G2: 257.61 | H2: Delivered
A3: ORD0002 | B3: 1002 | C3: Surat | D3: 46243 | E3: Rahul | F3: 38 | G3: 342.59 | H3: Delivered
A4: ORD0003 | B4: 1009 | C4: Rajkot | D4: 46257 | E4: Rahul | F4: 54 | G4: 313.22 | H4: Delivered
A5: ORD0004 | B5: 1005 | C5: Rajkot | D5: 46241 | E5: Neha | F5: 25 | G5: 220.68 | H5: Delivered
A6: ORD0005 | B6: 1006 | C6: Gandhinagar | D6: 46245 | E6: Karan | F6: 29 | G6: 336.58 | H6: Delivered
A7: ORD0006 | B7: 1009 | C7: Surat | D7: 46243 | E7: Karan | F7: 29 | G7: 173.89 | H7: Delivered
A8: ORD0007 | B8: 1009 | C8: Ahmedabad | D8: 46248 | E8: Karan | F8: 50 | G8: 128.13 | H8: Cancelled
A9: ORD0008 | B9: 1007 | C9: Surat | D9: 46244 | E9: Mehul | F9: 43 | G9: 220.6 | H9: Delivered
A10: ORD0009 | B10: 1010 | C10: Gandhinagar | D10: 46252 | E10: Sneha | F10: 51 | G10: 172.48 | H10: Delivered
A11: ORD0010 | B11: 1008 | C11: Vadodara | D11: 46238 | E11: Sneha | F11: 43 | G11: 58 | H11: Delivered
A12: ORD0011 | B12: 1009 | C12: Surat | D12: 46247 | E12: Rahul | F12: 24 | G12: 182.28 | H12: Delivered
A13: ORD0012 | B13: 1003 | C13: Ahmedabad | D13: 46252 | E13: Sneha | F13: 40 | G13: 95.45 | H13: Delivered
... A101: ORD0100 | B101: 1009 | C101: Ahmedabad | D101: 46253 | E101: Amit | F101: 52 | G101: 136.31 | H101: Cancelled

Sheet 02_Restaurant_Details
A1: Restaurant ID | B1: Restaurant Name | C1: Restaurant City
A2: 1001 | B2: Spice Hub | C2: Ahmedabad
A3: 1002 | B3: Urban Bites | C3: Surat
A4: 1003 | B4: Green Leaf Cafe | C4: Vadodara
A5: 1004 | B5: Royal Thali | C5: Ahmedabad
A6: 1005 | B6: Pizza Point | C6: Rajkot
A7: 1006 | B7: Dosa House | C7: Gandhinagar
A8: 1007 | B8: Burger Street | C8: Ahmedabad
A9: 1008 | B9: The Curry Bowl | C9: Surat
A10: 1009 | B10: Chai & Snacks | C10: Vadodara
A11: 1010 | B11: Food Junction | C11: Gandhinagar

Sheet 03_XLOOKUP_Result
A1: Order ID | B1: Restaurant ID | C1: City | D1: Delivery Date | E1: Delivery Partner | F1: Delivery Time (min) | G1: Delivery Charge | H1: Status | I1: Restaurant Name
A2: ORD0001 | B2: 1003 | C2: Surat | D2: 46235 | E2: Unassigned | F2: 29 | G2: 257.61 | H2: Delivered | I2: =XLOOKUP(B2,'02_Restaurant_Details'!$A$2:$A$11,'02_Restaurant_Details'!$B$2:$B$11,"Not Found")
A3: ORD0002 | B3: 1002 | C3: Surat | D3: 46243 | E3: Rahul | F3: 38 | G3: 342.59 | H3: Delivered | I3: =XLOOKUP(B3,'02_Restaurant_Details'!$A$2:$A$11,'02_Restaurant_Details'!$B$2:$B$11,"Not Found")
A4: ORD0003 | B4: 1009 | C4: Rajkot | D4: 46257 | E4: Rahul | F4: 54 | G4: 313.22 | H4: Delivered | I4: =XLOOKUP(B4,'02_Restaurant_Details'!$A$2:$A$11,'02_Restaurant_Details'!$B$2:$B$11,"Not Found")
A5: ORD0004 | B5: 1005 | C5: Rajkot | D5: 46241 | E5: Neha | F5: 25 | G5: 220.68 | H5: Delivered | I5: =XLOOKUP(B5,'02_Restaurant_Details'!$A$2:$A$11,'02_Restaurant_Details'!$B$2:$B$11,"Not Found")
A6: ORD0005 | B6: 1006 | C6: Gandhinagar | D6: 46245 | E6: Karan | F6: 29 | G6: 336.58 | H6: Delivered | I6: =XLOOKUP(B6,'02_Restaurant_Details'!$A$2:$A$11,'02_Restaurant_Details'!$B$2:$B$11,"Not Found")
A7: ORD0006 | B7: 1009 | C7: Surat | D7: 46243 | E7: Karan | F7: 29 | G7: 173.89 | H7: Delivered | I7: =XLOOKUP(B7,'02_Restaurant_Details'!$A$2:$A$11,'02_Restaurant_Details'!$B$2:$B$11,"Not Found")
A8: ORD0007 | B8: 1009 | C8: Ahmedabad | D8: 46248 | E8: Karan | F8: 50 | G8: 128.13 | H8: Cancelled | I8: =XLOOKUP(B8,'02_Restaurant_Details'!$A$2:$A$11,'02_Restaurant_Details'!$B$2:$B$11,"Not Found")
A9: ORD0008 | B9: 1007 | C9: Surat | D9: 46244 | E9: Mehul | F9: 43 | G9: 220.6 | H9: Delivered | I9: =XLOOKUP(B9,'02_Restaurant_Details'!$A$2:$A$11,'02_Restaurant_Details'!$B$2:$B$11,"Not Found")
A10: ORD0009 | B10: 1010 | C10: Gandhinagar | D10: 46252 | E10: Sneha | F10: 51 | G10: 172.48 | H10: Delivered | I10: =XLOOKUP(B10,'02_Restaurant_Details'!$A$2:$A$11,'02_Restaurant_Details'!$B$2:$B$11,"Not Found")
A11: ORD0010 | B11: 1008 | C11: Vadodara | D11: 46238 | E11: Sneha | F11: 43 | G11: 58 | H11: Delivered | I11: =XLOOKUP(B11,'02_Restaurant_Details'!$A$2:$A$11,'02_Restaurant_Details'!$B$2:$B$11,"Not Found")
A12: ORD0011 | B12: 1009 | C12: Surat | D12: 46247 | E12: Rahul | F12: 24 | G12: 182.28 | H12: Delivered | I12: =XLOOKUP(B12,'02_Restaurant_Details'!$A$2:$A$11,'02_Restaurant_Details'!$B$2:$B$11,"Not Found")
A13: ORD0012 | B13: 1003 | C13: Ahmedabad | D13: 46252 | E13: Sneha | F13: 40 | G13: 95.45 | H13: Delivered | I13: =XLOOKUP(B13,'02_Restaurant_Details'!$A$2:$A$11,'02_Restaurant_Details'!$B$2:$B$11,"Not Found")
... A101: ORD0100 | B101: 1009 | C101: Ahmedabad | D101: 46253 | E101: Amit | F101: 52 | G101: 136.31 | H101: Cancelled | I101: =XLOOKUP(B101,'02_Restaurant_Details'!$A$2:$A$11,'02_Restaurant_Details'!$B$2:$B$11,"Not Found")

Sheet 04_Day_Extraction
A1: Order ID | B1: Delivery Date | C1: Day of Week | D1: WEEKDAY Number
A2: ORD0001 | B2: 46235 | C2: =TEXT(B2,"dddd") | D2: =WEEKDAY(B2,2)
A3: ORD0002 | B3: 46243 | C3: =TEXT(B3,"dddd") | D3: =WEEKDAY(B3,2)
A4: ORD0003 | B4: 46257 | C4: =TEXT(B4,"dddd") | D4: =WEEKDAY(B4,2)
A5: ORD0004 | B5: 46241 | C5: =TEXT(B5,"dddd") | D5: =WEEKDAY(B5,2)
A6: ORD0005 | B6: 46245 | C6: =TEXT(B6,"dddd") | D6: =WEEKDAY(B6,2)
A7: ORD0006 | B7: 46243 | C7: =TEXT(B7,"dddd") | D7: =WEEKDAY(B7,2)
A8: ORD0007 | B8: 46248 | C8: =TEXT(B8,"dddd") | D8: =WEEKDAY(B8,2)
A9: ORD0008 | B9: 46244 | C9: =TEXT(B9,"dddd") | D9: =WEEKDAY(B9,2)
A10: ORD0009 | B10: 46252 | C10: =TEXT(B10,"dddd") | D10: =WEEKDAY(B10,2)
A11: ORD0010 | B11: 46238 | C11: =TEXT(B11,"dddd") | D11: =WEEKDAY(B11,2)
A12: ORD0011 | B12: 46247 | C12: =TEXT(B12,"dddd") | D12: =WEEKDAY(B12,2)
A13: ORD0012 | B13: 46252 | C13: =TEXT(B13,"dddd") | D13: =WEEKDAY(B13,2)
... A101: ORD0100 | B101: 46253 | C101: =TEXT(B101,"dddd") | D101: =WEEKDAY(B101,2)

Sheet 05_City_Summary
A1: City | B1: Total Orders | C1: Total Delivery Charges
A2: Ahmedabad | B2: =COUNTIF('01B_Cleaned_Orders'!$C$2:$C$101,A2) | C2: =SUMIF('01B_Cleaned_Orders'!$C$2:$C$101,A2,'01B_Cleaned_Orders'!$G$2:$G$101)
A3: Surat | B3: =COUNTIF('01B_Cleaned_Orders'!$C$2:$C$101,A3) | C3: =SUMIF('01B_Cleaned_Orders'!$C$2:$C$101,A3,'01B_Cleaned_Orders'!$G$2:$G$101)
A4: Vadodara | B4: =COUNTIF('01B_Cleaned_Orders'!$C$2:$C$101,A4) | C4: =SUMIF('01B_Cleaned_Orders'!$C$2:$C$101,A4,'01B_Cleaned_Orders'!$G$2:$G$101)
A5: Rajkot | B5: =COUNTIF('01B_Cleaned_Orders'!$C$2:$C$101,A5) | C5: =SUMIF('01B_Cleaned_Orders'!$C$2:$C$101,A5,'01B_Cleaned_Orders'!$G$2:$G$101)
A6: Gandhinagar | B6: =COUNTIF('01B_Cleaned_Orders'!$C$2:$C$101,A6) | C6: =SUMIF('01B_Cleaned_Orders'!$C$2:$C$101,A6,'01B_Cleaned_Orders'!$G$2:$G$101)

Sheet 06_Dashboard
A1: FOOD DELIVERY ANALYTICS MINI DASHBOARD
A3: KPI | B3: Value | D3: Top 3 Restaurants | E3: Orders | G3: City Filter / Slicer Area
A4: Total Orders | B4: =COUNTA('01B_Cleaned_Orders'!A2:A104) | D4: Spice Hub | E4: =COUNTIF('03_XLOOKUP_Result'!$I$2:$I$104,D4) | G4: Insert Slicer in Excel for City using PivotTable.
A5: Average Delivery Time | B5: =AVERAGE('01B_Cleaned_Orders'!F2:F104) | D5: Urban Bites | E5: =COUNTIF('03_XLOOKUP_Result'!$I$2:$I$104,D5) | G5: Use PivotTable/Charts connected to City field.
A6: Total Delivery Charges | B6: =SUM('01B_Cleaned_Orders'!G2:G104) | D6: Green Leaf Cafe | E6: =COUNTIF('03_XLOOKUP_Result'!$I$2:$I$104,D6) | G6: This workbook includes the source data and summary.
A9: Top 3 restaurant logic
A10: Create a PivotTable from 03_XLOOKUP_Result, put Restaurant Name in Rows and Order ID in Values (Count), sort descending, then apply Top 3 filter.

Sheet 07_Macro_Basic
A1: Task | B1: Expected Macro Action | C1: How to Verify
A2: 1 | B2: Enter your name in A1 and apply Bold | C2: Run Macro; A1 should show your name in bold
A3: 2 | B3: Format 10-order header and autofit columns | C3: Header formatted; columns fit contents
A4: 3 | B4: Save as .xlsm and reopen | C4: Enable macros and run a test macro

Sheet 08_Macro_10_Orders
A1: Order ID | B1: Restaurant | C1: Amount | D1: Status
A2: FD001 | B2: Spice Hub | C2: 250 | D2: Delivered
A3: FD002 | B3: Urban Bites | C3: 180 | D3: Delivered
A4: FD003 | B4: Pizza Point | C4: 420 | D4: Cancelled
A5: FD004 | B5: Dosa House | C5: 150 | D5: Delivered
A6: FD005 | B6: Burger Street | C6: 320 | D6: Delivered
A7: FD006 | B7: Royal Thali | C7: 275 | D7: Delivered
A8: FD007 | B8: Food Junction | C8: 199 | D8: Delivered
A9: FD008 | B9: Green Leaf Cafe | C9: 350 | D9: Cancelled
A10: FD009 | B10: Chai & Snacks | C10: 120 | D10: Delivered
A11: FD010 | B11: The Curry Bowl | C11: 290 | D11: Delivered

Sheet 09_Instagram_Followers
A1: Follower Name | C1: Macro task: delete blanks, sort A-Z, highlight names starting A in yellow.
A2: Zoya
A3: Amit
A4: Rahul
A6: Anjali
A7: Karan
A8: Aarav
A10: Bhavna
A11: Riya
A12: Arjun
A13: Neha
A14: Aakash
A15: Mehul

Sheet 10_VBA_Basics
A1: Task | B1: VBA Code
A2: 1 | B2: Sub WelcomeVBA() MsgBox "Welcome to VBA Programming!" End Sub
A3: 2 | B3: Sub DisplayVariables() Dim userName As String Dim orderCount As Integer Dim isPremiumUser As Boolean userName = "Jagadish" orderCount = 25 isPremiumUser = True MsgBox "User: " & userName & vbCrLf & _ "Orders: " & orderCount & vbCrLf & _ "Premium User: " & isPremiumUser End Sub
A4: 3 | B4: Sub CheckA1() If IsNumeric(Range("A1").Value) Then If Range("A1").Value > 100 Then Range("A1").Interior.Color = RGB(0, 255, 0) Else Range("A1").Interior.Color = RGB(255, 0, 0) End If Else MsgBox "A1 does not contain a number." End If End Sub
A5: 4 | B5: Sub FillRowNumbers() Dim i As Integer For i = 1 To 10 Cells(i, 1).Value = i Next i End Sub
A6: 5 | B6: Sub BoldAllSheets() Dim ws As Worksheet For Each ws In ThisWorkbook.Worksheets With ws.Range("A1:D1") .Font.Bold = True .Font.Size = 14 End With Next ws End Sub

Sheet 11_Recorded_Macro_Task
A1: Task | B1: Manual macro recorder steps
A2: Recorded Macro | B2: Developer > Record Macro > name it Highlight_A_Followers.
A3: Recorded Macro | B3: Delete blank rows from column A using Find/Select or filter, then sort column A A-Z. Stop Recording.
A4: Recorded Macro | B4: To highlight A names without VBA: select the follower range > Home > Conditional Formatting > Highlight Cells Rules > Text that Contains > enter A; OR use 'New Rule' formula =LEFT(A2,1)="A" and choose yellow fill. If the assignment specifically requires the recorder, record the formatting operation as part of the macro.
A5: Recorded Macro | B5: Run the macro and verify blanks are removed, names sorted, and A-starting names are yellow.

Sheet 12_IPL_Macro
A1: Match ID | B1: Team 1 | C1: Team 2 | D1: Winner | E1: Runs 1 | F1: Runs 2
A2: M001 | B2: MI | C2: CSK | D2: MI | E2: 198 | F2: 185
A3: M002 | B3: RCB | C3: GT | D3: GT | E3: 172 | F3: 176
A4: M003 | B4: MI | C4: KKR | D4: MI | E4: 201 | F4: 190
A5: M004 | B5: CSK | C5: RR | D5: RR | E5: 165 | F5: 170
A6: M005 | B6: RCB | C6: MI | D6: RCB | E6: 188 | F6: 182

Sheet 13_Clean_Playlist
A1: Track | B1: Artist | C1: Album
A2: Believer | B2: Imagine Dragons | C2: Evolve
A3: Shape of You | B3: Ed Sheeran | C3: Divide
A4: Perfect | B4: Ed Sheeran | C4: Divide
A5: Blinding Lights | B5: The Weeknd | C5: After Hours
A6: Believer | B6: Imagine Dragons | C6: Evolve

Sheet 14_Flipkart_Dashboard
A1: Order ID | B1: Product | C1: Category | D1: City | E1: Sales | F1: Quantity | H1: Button task
A2: FK001 | B2: Headphones | C2: Electronics | D2: Ahmedabad | E2: 48908 | F2: 1 | H2: Insert Form Control Button > Assign Refresh_All_Pivots
A3: FK002 | B3: Phone | C3: Electronics | D3: Gandhinagar | E3: 34313 | F3: 2 | H3: The VBA code is on 18_VBA_Code.
A4: FK003 | B4: Watch | C4: Electronics | D4: Ahmedabad | E4: 38313 | F4: 2
A5: FK004 | B5: Headphones | C5: Fashion | D5: Surat | E5: 18168 | F5: 4
A6: FK005 | B6: Headphones | C6: Electronics | D6: Gandhinagar | E6: 27263 | F6: 3
A7: FK006 | B7: Shoes | C7: Electronics | D7: Vadodara | E7: 24021 | F7: 5
A8: FK007 | B8: Shoes | C8: Fashion | D8: Surat | E8: 20881 | F8: 2
A9: FK008 | B9: Phone | C9: Fashion | D9: Vadodara | E9: 44626 | F9: 1
A10: FK009 | B10: Laptop | C10: Electronics | D10: Rajkot | E10: 23361 | F10: 5
A11: FK010 | B11: Headphones | C11: Electronics | D11: Gandhinagar | E11: 31694 | F11: 2
A12: FK011 | B12: Watch | C12: Fashion | D12: Surat | E12: 19664 | F12: 1
A13: FK012 | B13: Laptop | C13: Electronics | D13: Ahmedabad | E13: 38229 | F13: 5
A14: FK013 | B14: Watch | C14: Electronics | D14: Vadodara | E14: 6530 | F14: 1
A15: FK014 | B15: Shoes | C15: Fashion | D15: Vadodara | E15: 27977 | F15: 1
... A31: FK030 | B31: Headphones | C31: Fashion | D31: Rajkot | E31: 10240 | F31: 5

Sheet 15_Zomato_PDF
A1: ZOMATO SALES DASHBOARD
A3: Use this sheet as the dashboard to export.
A5: Required PDF filename: | B5: Zomato_Sales_Dashboard.pdf
A7: VBA macro is provided in 18_VBA_Code.

Sheet 16_PowerQuery_Refresh
A1: Task | B1: Details
A2: Refresh Power Query | B2: Use Data > Refresh All or the provided VBA macro.
A3: Success message | B3: Data refreshed successfully!
A4: Note | B4: The macro attempts to refresh workbook connections and then shows the message.

Sheet 17_Prompt_Used
A1: Item | B1: Content
A2: Prompt used with ChatGPT/Copilot | B2: Write a simple Excel VBA macro that refreshes all Power Query/workbook connections and then displays a message box saying "Data refreshed successfully!". Include basic error handling so the user receives a clear message if the refresh fails.

Sheet 18_VBA_Code
A1: Macro Name | B1: VBA Code | C1: Use For
A2: WriteNameBold | B2: Sub WriteNameBold() With ActiveSheet.Range("A1") .Value = "Jagadish Prajapati" .Font.Bold = True End With End Sub | C2: Basic recorded/manual macro task
A3: FormatFoodOrders | B3: Sub FormatFoodOrders() With ActiveSheet.Range("A1:D11") .Borders.LineStyle = xlContinuous End With With ActiveSheet.Range("A1:D1") .Font.Bold = True .Interior.Color = RGB(31, 78, 121) .Font.Color = RGB(255, 255, 255) End With ActiveSheet.Columns("A:D").AutoFit End Sub | C3: 10-order formatting
A4: CleanFollowers | B4: Sub CleanFollowers() Dim ws As Worksheet Dim lastRow As Long Set ws = ActiveSheet lastRow = ws.Cells(ws.Rows.Count, "A").End(xlUp).Row On Error Resume Next ws.Range("A2:A" & lastRow).SpecialCells(xlCellTypeBlanks).EntireRow.Delete On Error GoTo 0 lastRow = ws.Cells(ws.Rows.Count, "A").End(xlUp).Row ws.Range("A1:A" & lastRow).Sort Key1:=ws.Range("A2"), Order1:=xlAscending, Header:=xlYes End Sub | C4: Instagram followers task
A5: HighlightAFollowers | B5: Sub HighlightAFollowers() Dim c As Range For Each c In ActiveSheet.Range("A2:A" & ActiveSheet.Cells(Rows.Count, "A").End(xlUp).Row) If UCase(Left(Trim(c.Value), 1)) = "A" Then c.Interior.Color = RGB(255, 255, 0) End If Next c End Sub | C5: Highlight names beginning with A
A6: FormatIPL | B6: Sub FormatIPL() Dim ws As Worksheet Set ws = ActiveSheet With ws.Range("A1:F" & ws.Cells(ws.Rows.Count, "A").End(xlUp).Row) .Borders.LineStyle = xlContinuous End With With ws.Range("A1:F1") .Font.Bold = True .Interior.Color = RGB(31, 78, 121) .Font.Color = RGB(255, 255, 255) End With ws.Columns("A:F").AutoFit End Sub | C6: IPL formatting
A7: CleanPlaylistData | B7: Sub CleanPlaylistData() Dim ws As Worksheet Dim lastRow As Long, lastCol As Long Set ws = ActiveSheet lastRow = ws.Cells(ws.Rows.Count, 1).End(xlUp).Row lastCol = ws.Cells(1, ws.Columns.Count).End(xlToLeft).Column Dim rng As Range, cell As Range Set rng = ws.Range(ws.Cells(2, 1), ws.Cells(lastRow, lastCol)) For Each cell In rng If VarType(cell.Value) = vbString Then cell.Value = Application.WorksheetFunction.Trim(cell.Value) Next cell ws.Range(ws.Cells(1,1), ws.Cells(lastRow,lastCol)).RemoveDuplicates Columns:=Evaluate("ROW(1:" & lastCol & ")"), Header:=xlYes End Sub | C7: Spotify playlist cleaning
A8: Refresh_All_Pivots | B8: Sub Refresh_All_Pivots() ThisWorkbook.RefreshAll Dim ws As Worksheet, pt As PivotTable For Each ws In ThisWorkbook.Worksheets For Each pt In ws.PivotTables pt.RefreshTable Next pt Next ws MsgBox "PivotTables and dashboard data refreshed.", vbInformation End Sub | C8: Flipkart dashboard button
A9: Export_Zomato_PDF | B9: Sub Export_Zomato_PDF() Dim filePath As String Dim ws As Worksheet Set ws = ThisWorkbook.Worksheets("15_Zomato_PDF") filePath = Environ("USERPROFILE") & "\Desktop\Zomato_Sales_Dashboard.pdf" On Error Resume Next ws.ExportAsFixedFormat Type:=xlTypePDF, Filename:=filePath, Quality:=xlQualityStandard, _ IncludeDocProperties:=True, IgnorePrintAreas:=False, OpenAfterPublish:=False If Err.Number <> 0 Then MsgBox "PDF could not be saved: " & Err.Description, vbExclamation Err.Clear Else MsgBox "PDF exported successfully to Desktop.", vbInformation End If On Error GoTo 0 End Sub | C9: Export dashboard as PDF
A10: RefreshPowerQuery | B10: Sub RefreshPowerQuery() On Error GoTo ErrHandler ThisWorkbook.RefreshAll Application.CalculateUntilAsyncQueriesDone MsgBox "Data refreshed successfully!", vbInformation Exit Sub ErrHandler: MsgBox "Data refresh failed: " & Err.Description, vbExclamation End Sub | C10: Power Query refresh task
